Workbook
Name Capacity_Factor: Inputs_Assumptions!$E$29
Name Capacity_per_Turbine: Inputs_Assumptions!$E$26
Name CfD_Expiry_Date: Inputs_Assumptions!$E$99
Name CfD_Strike_Price: Inputs_Assumptions!$E$119
Name Circ_Ref: Inputs_Assumptions!#REF!
Name Constr_Contingency: Inputs_Assumptions!#REF!
Name Constr_Cost_per_kW: Inputs_Assumptions!#REF!
Name Constr_Debt_Pct: Inputs_Assumptions!$E$162
Name Constr_End_Date: Inputs_Assumptions!$E$83
Name Constr_Interest_Rate: Inputs_Assumptions!$E$163
Name Constr_P1: Inputs_Assumptions!$E$85
Name Constr_P2: Inputs_Assumptions!$E$86
Name Constr_P3: Inputs_Assumptions!$E$87
Name Constr_P4: Inputs_Assumptions!$E$88
Name Constr_P5: Inputs_Assumptions!$E$89
Name Constr_P6: Inputs_Assumptions!$E$90
Name Constr_P7: Inputs_Assumptions!$E$91
Name Constr_P8: Inputs_Assumptions!$E$92
Name Constr_Start_Date: Inputs_Assumptions!$E$82
Name Constr_Start_Quarter: Inputs_Assumptions!$E$84
Name Contigency: Inputs_Assumptions!$E$110
Name CPI_Escalation: Inputs_Assumptions!$E$127
Name Days_in_Year: Inputs_Assumptions!$E$15
Name DC_Cost_per_kW: Inputs_Assumptions!$E$104
Name Debt_Refinance_Date: Inputs_Assumptions!$E$98
Name Debt_Tenor: Inputs_Assumptions!$E$174
Name Degradation_Factor: Inputs_Assumptions!$E$76
Name Depr_Rate_Annual: Inputs_Assumptions!$E$135
Name Devex_Cost_per_kW: Inputs_Assumptions!$E$104
Name Electr_Rate: Inputs_Assumptions!$E$145
Name Electr_Rate_Escalation: Inputs_Assumptions!$E$157
Name Equity_In_Project: Inputs_Assumptions!$E$103
Name FID_Date: Inputs_Assumptions!$E$79
Name First_Debt_Interest: Inputs_Assumptions!$E$177
Name First_Interest_Quarterly: Inputs_Assumptions!$E$178
Name Fixed_Costs: Inputs_Assumptions!#REF!
Name Fixed_Escalation: Inputs_Assumptions!#REF!
Name Hours: Inputs_Assumptions!$E$11
Name Loan_Cmt_Fee_Pct: Inputs_Assumptions!$E$168
Name Loan_Upfront_Fee_Pct: Inputs_Assumptions!$E$167
Name Max_Debt_Draw: Inputs_Assumptions!$E$165
Name Merchant_Price: Inputs_Assumptions!$E$120
Name Million: Inputs_Assumptions!$E$24
Name Min_LLCR: Inputs_Assumptions!$E$186
Name Months_in_Quarter: Inputs_Assumptions!$E$12
Name Months_in_Year: Inputs_Assumptions!$E$13
Name Op_End_Date: Inputs_Assumptions!$E$101
Name Op_Start_Date: Inputs_Assumptions!$E$97
Name Oper_Debt_Pct: Inputs_Assumptions!#REF!
Name Operating_Debt_Pct: Inputs_Assumptions!#REF!
Name Quarters_in_Year: Inputs_Assumptions!$E$14
Name Refi_Q_Num: IRR_Revenue_Model!$E$13
Name Revenue_Escalation: Inputs_Assumptions!$E$126
Name RPI_Escalation: Inputs_Assumptions!$E$128
Name Scenario: Inputs_Assumptions!$E$141
Name Second_Debt_Interest: Inputs_Assumptions!$E$181
Name Second_Interest_Quarterly: Inputs_Assumptions!$E$182
Name Tax_Rate: Inputs_Assumptions!$E$22
Name Terminal_Exit_Date: Inputs_Assumptions!$E$100
Name Turbine_Min_Pct: Inputs_Assumptions!#REF!

Sheet Inputs_Assumptions
B2: =E7&" - Development and IRR Analysis" -> Norfolk Vanguard West - Development and IRR Analysis
B4: Development and Operating Assumptions: | D4: Units: | G4: Source | H4: Page Number | I4: Comments | J4: Link
C6: Project Name, Units, and Production Drivers:
C7: Project Name: | D7: Name | E7: Norfolk Vanguard West
C8: Asset Type: | D8: Name | E8: Energy
C9: Location: | D9: Name | E9: Norfolk England
C11: Hours in Day: | D11: # | E11: 24
C12: Months in Quarter: | D12: # | E12: 3
C13: Months in Year: | D13: # | E13: 12
C14: Quarters in Year: | D14: # | E14: 4
C15: Days in Year: | D15: # | E15: 365
C17: Hours in Q1: | D17: # | E17: 2160
C18: Hours in Q2: | D18: # | E18: 2184
C19: Hours in Q3: | D19: # | E19: 2208
C20: Hours in Q4: | D20: # | E20: 2208
C22: Tax Rate: | D22: % | E22: 0.25 | I22: UK corporation tax rate for profits over £250,000
C23: Units (kW to MW): | D23: # | E23: 1000
C24: Units (Million): | D24: # | E24: 1000000
C26: Installed Capacity per Turbine: | D26: MW | E26: 15 | G26: RWE Press Release | I26: Vestas V236-15.0 MW offshore wind turbines | J26: https://www.rwe.com/en/press/rwe-offshore-wind-gmbh/2026-02-20-rwe-and-vestas-agree-turbine-supply-agreement-for-vanguard-west-offshore-wind-farm/
C27: # of Turbines: | D27: # | E27: 103 | G27: RWE Press Release | I27: Number increased from press release to account for Unit B and Unit C | J27: https://www.rwe.com/en/press/rwe-offshore-wind-gmbh/2026-02-20-rwe-and-vestas-agree-turbine-supply-agreement-for-vanguard-west-offshore-wind-farm/
C28: Installed Capacity of Wind Farm | D28: MW | E28: =Capacity_per_Turbine*Turbines -> 1545 | I28: Unit A, B and C have 1380, 90 and 75 MW respectively
C29: Net Capacity Factor: | D29: % | E29: 0.505 | G29: DESNZ Arup Report | H29: 6, 23 | I29: Accounts for all relevant loss factors, including system availability (Wind Turbine Generator (WTG), Balance of Plant (BoP), and Grid), wake losses (internal and external), electrical system losses, turbine performance losses, and other secondary factor | J29: https://assets.publishing.service.gov.uk/media/6966a5c7e8c04eb2919f773d/lcoe-2024-offshore-wind.pdf
C30: Annual Gross Energy Output per Turbine: | D30: MWh | E30: =Capacity_per_Turbine*Hours*Days_in_Year -> 131400 | I30: Theoretical maximum energy produced if every turbine operated perfectly, with no losses, downtime, interference
C31: Annual Net Energy Output per Turbine: | D31: MWh | E31: =E30*Capacity_Factor -> 66357
C33: Initial Output Standard Deviation ("Uncertainty"): | D33: # | E33: 0.072 | G33: Published UK Offshore Wind Research | I33: Given revenue is almost entirely a function of how much wind blows which is uncertain, a P-value framework is used to quantify the uncertainty (via treating annual energy output probability distribution = If you modelled the annual energy output over 1000s of hypothetical years). IAV uncertainty of 4% (Potisomporn et al. 2022, UK Offshore specific) and model uncertainty of 6% (conservative mid-point, Lee & Fields 2021) combined give you a uncertainty of 7% | J33: https://docs.nlr.gov/docs/fy21osti/79631.pdf
C34: Turbine Net Energy Yields (Annual) P50 - 50% | D34: MWh | E34: =E31 -> 66357 | F34: =6827/Turbines -> 66.281553 | G34: =E34*Turbines/1000 -> 6834.771 | I34: For equity IRR and headline return to investors and investment thesis. Represents the expected outcome if you owned an asset across its full lifecycle
C35: Turbine Net Energy Yields (Annual) P75 - 25% | D35: MWh | E35: =_xlfn.NORM.INV(25%,$E$34,$E$33*$E$31) -> 63134.488 | F35: =6495/Turbines -> 63.058252 | G35: =E35*Turbines/1000 -> 6502.8522 | I35: For equity sensitivity analysis. Represents the outcome for a roughly bad year and to check if you still get a acceptable equity return
C36: Turbine Net Energy Yields (Annual) P90 - 10% | D36: MWh | E36: =_xlfn.NORM.INV(10%,$E$34,$E$33*$E$31) -> 60234.126 | F36: =6198/Turbines -> 60.174757 | G36: =E36*Turbines/1000 -> 6204.115 | I36: For debt sizing case. Debt lenders want to ensure the project can service the debt in P90 year (once per decade). The DSCR must be above the covenant floor at event P90
C37: Turbine Net Energy Yields (Annual) P99 - 1% | D37: MWh | E37: =_xlfn.NORM.INV(1%,$E$34,$E$33*$E$31) -> 55242.398 | F37: =5683/Turbines -> 55.174757 | G37: =E37*Turbines/1000 -> 5689.967 | I37: For worst case scenario. Used to answer 2 questions: 1) Can the project survive a P99 year without breaching debt covenants or requiring equity payments 2) Does the project generate enough cash flow to cover fixed obligations (debt service, O&M, insurance) without drawing on reserves
C38: Turbine Net Energy Yields (Annual) P50 - 50% | D38: % | E38: =E34/$E$34 -> 1
C39: Turbine Net Energy Yields (Annual) P75 - 25% | D39: % | E39: =E35/$E$34 -> 0.95143674
C40: Turbine Net Energy Yields (Annual) P90 - 10% | D40: % | E40: =E36/$E$34 -> 0.90772829
C41: Turbine Net Energy Yields (Annual) P99 - 1% | D41: % | E41: =E37/$E$34 -> 0.83250295
C43: Production Seasonality Avg Load Factor (Q1) | D43: % | E43: 0.483 | G43: DESNZ Energy Trends: UK Renewables | H43: Tab 6_1 | I43: Average offshore wind load factors used from 2015 Q2 to 2025 Q3 where offshore wind capacity is > 5GW | J43: https://www.gov.uk/government/statistics/energy-trends-section-6-renewables
C44: Production Seasonality Avg Load Factor (Q2) | D44: % | E44: 0.303 | G44: DESNZ Energy Trends: UK Renewables | H44: Tab 6_1 | I44: Average offshore wind load factors used from 2015 Q2 to 2025 Q3 where offshore wind capacity is > 5GW | J44: https://www.gov.uk/government/statistics/energy-trends-section-6-renewables
C45: Production Seasonality Avg Load Factor (Q3) | D45: % | E45: 0.305 | G45: DESNZ Energy Trends: UK Renewables | H45: Tab 6_1 | I45: Average offshore wind load factors used from 2015 Q2 to 2025 Q3 where offshore wind capacity is > 5GW | J45: https://www.gov.uk/government/statistics/energy-trends-section-6-renewables
C46: Production Seasonality Avg Load Factor (Q4) | D46: % | E46: 0.487 | G46: DESNZ Energy Trends: UK Renewables | H46: Tab 6_1 | I46: Average offshore wind load factors used from 2015 Q2 to 2025 Q3 where offshore wind capacity is > 5GW | J46: https://www.gov.uk/government/statistics/energy-trends-section-6-renewables
C48: Production Generation Index (Q1) | D48: hours | E48: =E43*E17 -> 1043.28 | I48: 2160 hours in Q1
C49: Production Generation Index (Q2) | D49: hours | E49: =E44*E18 -> 661.752 | I49: 2184 hours in Q2
C50: Production Generation Index (Q3) | D50: hours | E50: =E45*E19 -> 673.44 | I50: 2208 hours in Q3
...

Sheet Constr_Phase_Model
B2: Development & Construction Projections
G4: Calendar Year 1: | K4: Calendar Year 2: | O4: Calendar Year 3: | S4: Calendar Year 4: | W4: Calendar Year 5:
B5: Debt and Equity Draws: | D5: =+Inputs_Assumptions!$D$4 -> Units: | E5: Total: | G5: =IRR_Revenue_Model!$G$5 -> 46112 | H5: =IRR_Revenue_Model!$H$5 -> 46203 | I5: =IRR_Revenue_Model!$I$5 -> 46295 | J5: =IRR_Revenue_Model!$J$5 -> 46387 | K5: =IRR_Revenue_Model!$K$5 -> 46477 | L5: =IRR_Revenue_Model!$L$5 -> 46568 | M5: =IRR_Revenue_Model!$M$5 -> 46660 | N5: =IRR_Revenue_Model!$N$5 -> 46752 | O5: =IRR_Revenue_Model!$O$5 -> 46843 | P5: =IRR_Revenue_Model!$P$5 -> 46934 | Q5: =IRR_Revenue_Model!$Q$5 -> 47026 | R5: =IRR_Revenue_Model!$R$5 -> 47118 | S5: =IRR_Revenue_Model!$S$5 -> 47208 | T5: =IRR_Revenue_Model!$T$5 -> 47299 | U5: =IRR_Revenue_Model!$U$5 -> 47391 | V5: =IRR_Revenue_Model!$V$5 -> 47483 | W5: =IRR_Revenue_Model!$W$5 -> 47573 | X5: =IRR_Revenue_Model!$X$5 -> 47664 | Y5: =IRR_Revenue_Model!$Y$5 -> 47756 | Z5: =IRR_Revenue_Model!$Z$5 -> 47848
C7: Construction Period: | D7: # | E7: =COUNTIF(G7:Z7,">0") -> 11 | G7: =IF(AND(G5>Constr_Start_Date,G5<=Constr_P8),1,0) -> 0 | H7: =IF(AND(H5>Constr_Start_Date,H5<=Constr_P8),1,0) -> 0 | I7: =IF(AND(I5>Constr_Start_Date,I5<=Constr_P8),1,0) -> 1 | J7: =IF(AND(J5>Constr_Start_Date,J5<=Constr_P8),1,0) -> 1 | K7: =IF(AND(K5>Constr_Start_Date,K5<=Constr_P8),1,0) -> 1 | L7: =IF(AND(L5>Constr_Start_Date,L5<=Constr_P8),1,0) -> 1 | M7: =IF(AND(M5>Constr_Start_Date,M5<=Constr_P8),1,0) -> 1 | N7: =IF(AND(N5>Constr_Start_Date,N5<=Constr_P8),1,0) -> 1 | ... Z7: =IF(AND(Z5>Constr_Start_Date,Z5<=Constr_P8),1,0) -> 0
C8: Total Operational Turbines: | D8: # | E8: =S8 -> 103 | G8: {=_xlfn.IFS(G5>=Constr_P8,Inputs_Assumptions!$F$92,G5>=Constr_P7,Inputs_Assumptions!$F$91,G5>=Constr_P6,Inputs_Assumptions!$F$90,G5>=Constr_P5,Inputs_Assumptions!$F$89,G5>=Constr_P4,Inputs_Assumptions!$F$88,G5>=Constr_P3,Inputs_Assumptions!$F$87,G5>=Constr_P2,Inputs_Assumptions!$F$86,G5>=Constr_P1,Inputs_Assumptions!$F$85,"TRUE",0)} -> 0 | H8: {=_xlfn.IFS(H5>=Constr_P8,Inputs_Assumptions!$F$92,H5>=Constr_P7,Inputs_Assumptions!$F$91,H5>=Constr_P6,Inputs_Assumptions!$F$90,H5>=Constr_P5,Inputs_Assumptions!$F$89,H5>=Constr_P4,Inputs_Assumptions!$F$88,H5>=Constr_P3,Inputs_Assumptions!$F$87,H5>=Constr_P2,Inputs_Assumptions!$F$86,H5>=Constr_P1,Inputs_Assumptions!$F$85,"TRUE",0)} -> 0 | I8: {=_xlfn.IFS(I5>=Constr_P8,Inputs_Assumptions!$F$92,I5>=Constr_P7,Inputs_Assumptions!$F$91,I5>=Constr_P6,Inputs_Assumptions!$F$90,I5>=Constr_P5,Inputs_Assumptions!$F$89,I5>=Constr_P4,Inputs_Assumptions!$F$88,I5>=Constr_P3,Inputs_Assumptions!$F$87,I5>=Constr_P2,Inputs_Assumptions!$F$86,I5>=Constr_P1,Inputs_Assumptions!$F$85,"TRUE",0)} -> 0 | J8: {=_xlfn.IFS(J5>=Constr_P8,Inputs_Assumptions!$F$92,J5>=Constr_P7,Inputs_Assumptions!$F$91,J5>=Constr_P6,Inputs_Assumptions!$F$90,J5>=Constr_P5,Inputs_Assumptions!$F$89,J5>=Constr_P4,Inputs_Assumptions!$F$88,J5>=Constr_P3,Inputs_Assumptions!$F$87,J5>=Constr_P2,Inputs_Assumptions!$F$86,J5>=Constr_P1,Inputs_Assumptions!$F$85,"TRUE",0)} -> 0 | K8: {=_xlfn.IFS(K5>=Constr_P8,Inputs_Assumptions!$F$92,K5>=Constr_P7,Inputs_Assumptions!$F$91,K5>=Constr_P6,Inputs_Assumptions!$F$90,K5>=Constr_P5,Inputs_Assumptions!$F$89,K5>=Constr_P4,Inputs_Assumptions!$F$88,K5>=Constr_P3,Inputs_Assumptions!$F$87,K5>=Constr_P2,Inputs_Assumptions!$F$86,K5>=Constr_P1,Inputs_Assumptions!$F$85,"TRUE",0)} -> 0 | L8: {=_xlfn.IFS(L5>=Constr_P8,Inputs_Assumptions!$F$92,L5>=Constr_P7,Inputs_Assumptions!$F$91,L5>=Constr_P6,Inputs_Assumptions!$F$90,L5>=Constr_P5,Inputs_Assumptions!$F$89,L5>=Constr_P4,Inputs_Assumptions!$F$88,L5>=Constr_P3,Inputs_Assumptions!$F$87,L5>=Constr_P2,Inputs_Assumptions!$F$86,L5>=Constr_P1,Inputs_Assumptions!$F$85,"TRUE",0)} -> 6 | M8: {=_xlfn.IFS(M5>=Constr_P8,Inputs_Assumptions!$F$92,M5>=Constr_P7,Inputs_Assumptions!$F$91,M5>=Constr_P6,Inputs_Assumptions!$F$90,M5>=Constr_P5,Inputs_Assumptions!$F$89,M5>=Constr_P4,Inputs_Assumptions!$F$88,M5>=Constr_P3,Inputs_Assumptions!$F$87,M5>=Constr_P2,Inputs_Assumptions!$F$86,M5>=Constr_P1,Inputs_Assumptions!$F$85,"TRUE",0)} -> 22 | N8: {=_xlfn.IFS(N5>=Constr_P8,Inputs_Assumptions!$F$92,N5>=Constr_P7,Inputs_Assumptions!$F$91,N5>=Constr_P6,Inputs_Assumptions!$F$90,N5>=Constr_P5,Inputs_Assumptions!$F$89,N5>=Constr_P4,Inputs_Assumptions!$F$88,N5>=Constr_P3,Inputs_Assumptions!$F$87,N5>=Constr_P2,Inputs_Assumptions!$F$86,N5>=Constr_P1,Inputs_Assumptions!$F$85,"TRUE",0)} -> 30 | ... Z8: {=_xlfn.IFS(Z5>=Constr_P8,Inputs_Assumptions!$F$92,Z5>=Constr_P7,Inputs_Assumptions!$F$91,Z5>=Constr_P6,Inputs_Assumptions!$F$90,Z5>=Constr_P5,Inputs_Assumptions!$F$89,Z5>=Constr_P4,Inputs_Assumptions!$F$88,Z5>=Constr_P3,Inputs_Assumptions!$F$87,Z5>=Constr_P2,Inputs_Assumptions!$F$86,Z5>=Constr_P1,Inputs_Assumptions!$F$85,"TRUE",0)} -> 103
C9: Percentage of Construction Capex Costs: | D9: % | E9: =SUM(G9:Z9) -> 1 | G9: =(H8-G8)/$E$8 -> 0 | H9: =(I8-H8)/$E$8 -> 0 | I9: =(J8-I8)/$E$8 -> 0 | J9: =(K8-J8)/$E$8 -> 0 | K9: 0 | L9: =(L8)/$E$8 -> 0.058252427 | M9: =(M8-L8)/$E$8 -> 0.15533981 | N9: =(N8-M8)/$E$8 -> 0.077669903 | O9: =(O8-N8)/$E$8 -> 0.067961165 | P9: =(P8-O8)/$E$8 -> 0.22330097 | Q9: =(Q8-P8)/$E$8 -> 0.24271845 | R9: =(R8-Q8)/$E$8 -> 0.11650485 | S9: =(S8-R8)/$E$8 -> 0.058252427 | T9: =(U8-T8)/$E$8 -> 0 | U9: =(V8-U8)/$E$8 -> 0 | V9: 0 | W9: 0 | X9: 0 | Y9: 0 | Z9: 0
C10: Percentage of Infrastructure Capex Costs: | D10: % | E10: =SUM(G10:Z10) -> 1 | G10: 0 | H10: 0 | I10: =L9 -> 0.058252427 | J10: =M9 -> 0.15533981 | K10: =N9 -> 0.077669903 | L10: =O9 -> 0.067961165 | M10: =P9 -> 0.22330097 | N10: =Q9 -> 0.24271845 | O10: =R9 -> 0.11650485 | P10: =S9 -> 0.058252427 | Q10: =T9 -> 0 | R10: =Q10 -> 0 | S10: =R10 -> 0 | T10: =S10 -> 0 | U10: =T10 -> 0 | V10: =U10 -> 0 | W10: =V10 -> 0 | X10: =W10 -> 0 | Y10: =X10 -> 0 | Z10: =Y10 -> 0
C13: (+) Construction Capex Costs: | D13: £ M | E13: =SUM(G13:Z13) -> 1949.79 | G13: =(Inputs_Assumptions!$E$28*Inputs_Assumptions!$E$108*1000/Million)*G9*Equity_In_Project -> 0 | H13: =(Inputs_Assumptions!$E$28*Inputs_Assumptions!$E$108*1000/Million)*H9*Equity_In_Project -> 0 | I13: =(Inputs_Assumptions!$E$28*Inputs_Assumptions!$E$108*1000/Million)*I9*Equity_In_Project -> 0 | J13: =(Inputs_Assumptions!$E$28*Inputs_Assumptions!$E$108*1000/Million)*J9*Equity_In_Project -> 0 | K13: =(Inputs_Assumptions!$E$28*Inputs_Assumptions!$E$108*1000/Million)*K9*Equity_In_Project -> 0 | L13: =(Inputs_Assumptions!$E$28*Inputs_Assumptions!$E$108*1000/Million)*L9*Equity_In_Project -> 113.58 | M13: =(Inputs_Assumptions!$E$28*Inputs_Assumptions!$E$108*1000/Million)*M9*Equity_In_Project -> 302.88 | N13: =(Inputs_Assumptions!$E$28*Inputs_Assumptions!$E$108*1000/Million)*N9*Equity_In_Project -> 151.44 | ... Z13: =(Inputs_Assumptions!$E$28*Inputs_Assumptions!$E$108*1000/Million)*Z9*Equity_In_Project -> 0
C14: (+) Infrastructure Capex Costs: | D14: £ M | E14: =SUM(G14:Z14) -> 424.875 | G14: =(Inputs_Assumptions!$E$28*Inputs_Assumptions!$E$109*1000/Million)*G10*Equity_In_Project -> 0 | H14: =(Inputs_Assumptions!$E$28*Inputs_Assumptions!$E$109*1000/Million)*H10*Equity_In_Project -> 0 | I14: =(Inputs_Assumptions!$E$28*Inputs_Assumptions!$E$109*1000/Million)*I10*Equity_In_Project -> 24.75 | J14: =(Inputs_Assumptions!$E$28*Inputs_Assumptions!$E$109*1000/Million)*J10*Equity_In_Project -> 66 | K14: =(Inputs_Assumptions!$E$28*Inputs_Assumptions!$E$109*1000/Million)*K10*Equity_In_Project -> 33 | L14: =(Inputs_Assumptions!$E$28*Inputs_Assumptions!$E$109*1000/Million)*L10*Equity_In_Project -> 28.875 | M14: =(Inputs_Assumptions!$E$28*Inputs_Assumptions!$E$109*1000/Million)*M10*Equity_In_Project -> 94.875 | N14: =(Inputs_Assumptions!$E$28*Inputs_Assumptions!$E$109*1000/Million)*N10*Equity_In_Project -> 103.125 | ... Z14: =(Inputs_Assumptions!$E$28*Inputs_Assumptions!$E$109*1000/Million)*Z10*Equity_In_Project -> 0
C15: (+) Contigency Costs: | D15: £ M | E15: =SUM(G15:Z15) -> 59.366625 | G15: =SUM(G13:G14)*Contigency -> 0 | H15: =SUM(H13:H14)*Contigency -> 0 | I15: =SUM(I13:I14)*Contigency -> 0.61875 | J15: =SUM(J13:J14)*Contigency -> 1.65 | K15: =SUM(K13:K14)*Contigency -> 0.825 | L15: =SUM(L13:L14)*Contigency -> 3.561375 | M15: =SUM(M13:M14)*Contigency -> 9.943875 | N15: =SUM(N13:N14)*Contigency -> 6.364125 | ... Z15: =SUM(Z13:Z14)*Contigency -> 0
C16: (+) Debt Service Reserve Account Costs: | D16: £ M | E16: =SUM(G16:Z16) -> 60.613922 | G16: =IF(G5<=Debt_Refinance_Date,IRR_Revenue_Model!G114,0) -> 0 | H16: =IF(H5<=Debt_Refinance_Date,IRR_Revenue_Model!H114,0) -> 0 | I16: =IF(I5<=Debt_Refinance_Date,IRR_Revenue_Model!I114,0) -> 0 | J16: =IF(J5<=Debt_Refinance_Date,IRR_Revenue_Model!J114,0) -> 0 | K16: =IF(K5<=Debt_Refinance_Date,IRR_Revenue_Model!K114,0) -> 0 | L16: =IF(L5<=Debt_Refinance_Date,IRR_Revenue_Model!L114,0) -> 0 | M16: =IF(M5<=Debt_Refinance_Date,IRR_Revenue_Model!M114,0) -> 0 | N16: =IF(N5<=Debt_Refinance_Date,IRR_Revenue_Model!N114,0) -> 0 | ... V16: =IF(V5<=Debt_Refinance_Date,IRR_Revenue_Model!V114,0) -> 30.961047 | W16: =IF(W5<=Debt_Refinance_Date,IRR_Revenue_Model!W114-IRR_Revenue_Model!V114,0) -> 29.652874 | X16: =IF(X5<=Debt_Refinance_Date,IRR_Revenue_Model!X114,0) -> 0 | Y16: =IF(Y5<=Debt_Refinance_Date,IRR_Revenue_Model!Y114,0) -> 0 | Z16: =IF(Z5<=Debt_Refinance_Date,IRR_Revenue_Model!Z114,0) -> 0
C17: Total Construction Capex Costs: | D17: £ M | E17: =SUM(G17:Z17) -> 2494.6455 | G17: =SUM(G13:G16) -> 0 | H17: =SUM(H13:H16) -> 0 | I17: =SUM(I13:I16) -> 25.36875 | J17: =SUM(J13:J16) -> 67.65 | K17: =SUM(K13:K16) -> 33.825 | L17: =SUM(L13:L16) -> 146.01637 | M17: =SUM(M13:M16) -> 407.69887 | N17: =SUM(N13:N16) -> 260.92912 | ... Z17: =SUM(Z13:Z16) -> 0
C19: (+) Interest During Construction (IDC): | D19: £ M | E19: =SUM(G19:Z19) -> 149.30938 | G19: =IF(AND(G5>FID_Date,G5<Debt_Refinance_Date),G31*Inputs_Assumptions!$E$164,0) -> 0 | H19: =IF(AND(H5>FID_Date,H5<Debt_Refinance_Date),H31*Inputs_Assumptions!$E$164,0) -> 0 | I19: =IF(AND(I5>FID_Date,I5<Debt_Refinance_Date),I31*Inputs_Assumptions!$E$164,0) -> 0 | J19: =IF(AND(J5>FID_Date,J5<Debt_Refinance_Date),J31*Inputs_Assumptions!$E$164,0) -> 0.46221678 | K19: =IF(AND(K5>FID_Date,K5<Debt_Refinance_Date),K31*Inputs_Assumptions!$E$164,0) -> 1.1328001 | L19: =IF(AND(L5>FID_Date,L5<Debt_Refinance_Date),L31*Inputs_Assumptions!$E$164,0) -> 1.4938109 | M19: =IF(AND(M5>FID_Date,M5<Debt_Refinance_Date),M31*Inputs_Assumptions!$E$164,0) -> 2.9014864 | N19: =IF(AND(N5>FID_Date,N5<Debt_Refinance_Date),N31*Inputs_Assumptions!$E$164,0) -> 6.7045939 | ... Z19: =IF(AND(Z5>FID_Date,Z5<Debt_Refinance_Date),Z31*Inputs_Assumptions!$E$164,0) -> 0
C20: (+) Upfront Loan Fees: | D20: £ M | E20: =SUM(G20:Z20) -> 20.268995 | G20: =IF(AND(F7<>1,G7=1),Max_Debt_Draw*Loan_Upfront_Fee_Pct,0) -> 0 | H20: =IF(AND(G7<>1,H7=1),Max_Debt_Draw*Loan_Upfront_Fee_Pct,0) -> 0 | I20: =IF(AND(H7<>1,I7=1),Max_Debt_Draw*Loan_Upfront_Fee_Pct,0) -> 20.268995 | J20: =IF(AND(I7<>1,J7=1),Max_Debt_Draw*Loan_Upfront_Fee_Pct,0) -> 0 | K20: =IF(AND(J7<>1,K7=1),Max_Debt_Draw*Loan_Upfront_Fee_Pct,0) -> 0 | L20: =IF(AND(K7<>1,L7=1),Max_Debt_Draw*Loan_Upfront_Fee_Pct,0) -> 0 | M20: =IF(AND(L7<>1,M7=1),Max_Debt_Draw*Loan_Upfront_Fee_Pct,0) -> 0 | N20: =IF(AND(M7<>1,N7=1),Max_Debt_Draw*Loan_Upfront_Fee_Pct,0) -> 0 | ... Z20: =IF(AND(Y7<>1,Z7=1),Max_Debt_Draw*Loan_Upfront_Fee_Pct,0) -> 0
C21: (+) Loan Commitment Fees: | D21: £ M | E21: =SUM(G21:Z21) -> 30.562564 | G21: =IF(AND(G5>FID_Date,G5<Debt_Refinance_Date),G28*Inputs_Assumptions!$E$169,0) -> 0 | H21: =IF(AND(H5>FID_Date,H5<Debt_Refinance_Date),H28*Inputs_Assumptions!$E$169,0) -> 0 | I21: =IF(AND(I5>FID_Date,I5<Debt_Refinance_Date),I28*Inputs_Assumptions!$E$169,0) -> 4.0386853 | J21: =IF(AND(J5>FID_Date,J5<Debt_Refinance_Date),J28*Inputs_Assumptions!$E$169,0) -> 3.9582621 | K21: =IF(AND(K5>FID_Date,K5<Debt_Refinance_Date),K28*Inputs_Assumptions!$E$169,0) -> 3.8415842 | L21: =IF(AND(L5>FID_Date,L5<Debt_Refinance_Date),L28*Inputs_Assumptions!$E$169,0) -> 3.7787703 | M21: =IF(AND(M5>FID_Date,M5<Debt_Refinance_Date),M28*Inputs_Assumptions!$E$169,0) -> 3.5338423 | N21: =IF(AND(N5>FID_Date,N5<Debt_Refinance_Date),N28*Inputs_Assumptions!$E$169,0) -> 2.872122 | ... Z21: =IF(AND(Z5>FID_Date,Z5<Debt_Refinance_Date),Z28*Inputs_Assumptions!$E$169,0) -> 0
C22: Total Construction Costs: | D22: £ M | E22: =SUM(G22:Z22) -> 2694.7865 | G22: =SUM(G13:G16)+SUM(G19:G21) -> 0 | H22: =SUM(H13:H16)+SUM(H19:H21) -> 0 | I22: =SUM(I13:I16)+SUM(I19:I21) -> 49.67643 | J22: =SUM(J13:J16)+SUM(J19:J21) -> 72.070479 | K22: =SUM(K13:K16)+SUM(K19:K21) -> 38.799384 | L22: =SUM(L13:L16)+SUM(L19:L21) -> 151.28896 | M22: =SUM(M13:M16)+SUM(M19:M21) -> 414.1342 | N22: =SUM(N13:N16)+SUM(N19:N21) -> 270.50584 | ... Z22: =SUM(Z13:Z16)+SUM(Z19:Z21) -> 0
C24: Equity Draw: | D24: £ M | E24: =SUM(G24:Z24) -> 921.9604 | G24: =IF(AND(G5>FID_Date,G5<Debt_Refinance_Date),IF(G16>0,(G22-G16)*(1-Constr_Debt_Pct),G22*(1-Constr_Debt_Pct)),0) -> 0 | H24: =IF(AND(H5>FID_Date,H5<Debt_Refinance_Date),IF(H16>0,(H22-H16)*(1-Constr_Debt_Pct),H22*(1-Constr_Debt_Pct)),0) -> 0 | I24: =IF(AND(I5>FID_Date,I5<Debt_Refinance_Date),IF(I16>0,(I22-I16)*(1-Constr_Debt_Pct),I22*(1-Constr_Debt_Pct)),0) -> 17.386751 | J24: =IF(AND(J5>FID_Date,J5<Debt_Refinance_Date),IF(J16>0,(J22-J16)*(1-Constr_Debt_Pct),J22*(1-Constr_Debt_Pct)),0) -> 25.224668 | K24: =IF(AND(K5>FID_Date,K5<Debt_Refinance_Date),IF(K16>0,(K22-K16)*(1-Constr_Debt_Pct),K22*(1-Constr_Debt_Pct)),0) -> 13.579785 | L24: =IF(AND(L5>FID_Date,L5<Debt_Refinance_Date),IF(L16>0,(L22-L16)*(1-Constr_Debt_Pct),L22*(1-Constr_Debt_Pct)),0) -> 52.951135 | M24: =IF(AND(M5>FID_Date,M5<Debt_Refinance_Date),IF(M16>0,(M22-M16)*(1-Constr_Debt_Pct),M22*(1-Constr_Debt_Pct)),0) -> 144.94697 | N24: =IF(AND(N5>FID_Date,N5<Debt_Refinance_Date),IF(N16>0,(N22-N16)*(1-Constr_Debt_Pct),N22*(1-Constr_Debt_Pct)),0) -> 94.677044 | ... Z24: =IF(AND(Z5>FID_Date,Z5<Debt_Refinance_Date),IF(Z16>0,(Z22-Z16)*(1-Constr_Debt_Pct),Z22*(1-Constr_Debt_Pct)),0) -> 0
C25: Construction Loan Draw (Without Repayment during Construction): | D25: £ M | E25: =SUM(G25:Z25) -> 1772.8261 | G25: =G22-G24 -> 0 | H25: =H22-H24 -> 0 | I25: =I22-I24 -> 32.28968 | J25: =J22-J24 -> 46.845811 | K25: =K22-K24 -> 25.2196 | L25: =L22-L24 -> 98.337821 | M25: =M22-M24 -> 269.18723 | N25: =N22-N24 -> 175.8288 | ... Z25: =Z22-Z24 -> 0
C26: Construction Loan Draw (Repayment during Construction): | D26: £ M | E26: =SUM(G26:Z26) -> 1381.2446 | G26: =IF(G5<=Debt_Refinance_Date,G25-IRR_Revenue_Model!G89,0) -> 0 | H26: =IF(H5<=Debt_Refinance_Date,H25-IRR_Revenue_Model!H89,0) -> 0 | I26: =IF(I5<=Debt_Refinance_Date,I25-IRR_Revenue_Model!I89,0) -> 32.28968 | J26: =IF(J5<=Debt_Refinance_Date,J25-IRR_Revenue_Model!J89,0) -> 46.845811 | K26: =IF(K5<=Debt_Refinance_Date,K25-IRR_Revenue_Model!K89,0) -> 25.2196 | L26: =IF(L5<=Debt_Refinance_Date,L25-IRR_Revenue_Model!L89,0) -> 98.337821 | M26: =IF(M5<=Debt_Refinance_Date,M25-IRR_Revenue_Model!M89,0) -> 265.67864 | N26: =IF(N5<=Debt_Refinance_Date,N25-IRR_Revenue_Model!N89,0) -> 160.57438 | ... Z26: =IF(Z5<=Debt_Refinance_Date,Z25-IRR_Revenue_Model!Z89,0) -> 0
C28: Undrawn Loan: | D28: £ M | G28: =IF(AND(G5>Constr_Start_Date,G5<Debt_Refinance_Date),Max_Debt_Draw-G31,0) -> 0 | H28: =IF(AND(H5>Constr_Start_Date,H5<Debt_Refinance_Date),Max_Debt_Draw-H31,0) -> 0 | I28: =IF(AND(I5>Constr_Start_Date,I5<Debt_Refinance_Date),Max_Debt_Draw-I31,0) -> 1621.5196 | J28: =IF(AND(J5>Constr_Start_Date,J5<Debt_Refinance_Date),Max_Debt_Draw-J31,0) -> 1589.2299 | K28: =IF(AND(K5>Constr_Start_Date,K5<Debt_Refinance_Date),Max_Debt_Draw-K31,0) -> 1542.3841 | L28: =IF(AND(L5>Constr_Start_Date,L5<Debt_Refinance_Date),Max_Debt_Draw-L31,0) -> 1517.1645 | M28: =IF(AND(M5>Constr_Start_Date,M5<Debt_Refinance_Date),Max_Debt_Draw-M31,0) -> 1418.8267 | N28: =IF(AND(N5>Constr_Start_Date,N5<Debt_Refinance_Date),Max_Debt_Draw-N31,0) -> 1153.1481 | ... Z28: =IF(AND(Z5>Constr_Start_Date,Z5<Debt_Refinance_Date),Max_Debt_Draw-Z31,0) -> 0
C30: Construction Loan:
C31: Beginning Debt Balance: | D31: £ M | G31: 0 | H31: =G33 -> 0 | I31: =H33 -> 0 | J31: =I33 -> 32.28968 | K31: =J33 -> 79.135491 | L31: =K33 -> 104.35509 | M31: =L33 -> 202.69291 | N31: =M33 -> 468.37155 | O31: =N33 -> 628.94593 | ... Z31: =Y33 -> 1381.2446
C32: (+) Draws: | D32: £ M | G32: =G26 -> 0 | H32: =H26 -> 0 | I32: =I26 -> 32.28968 | J32: =J26 -> 46.845811 | K32: =K26 -> 25.2196 | L32: =L26 -> 98.337821 | M32: =M26 -> 265.67864 | N32: =N26 -> 160.57438 | ... Z32: =Z26 -> 0
C33: Ending Debt Balance: | D33: £ M | G33: =SUM(G31:G32) -> 0 | H33: =SUM(H31:H32) -> 0 | I33: =SUM(I31:I32) -> 32.28968 | J33: =SUM(J31:J32) -> 79.135491 | K33: =SUM(K31:K32) -> 104.35509 | L33: =SUM(L31:L32) -> 202.69291 | M33: =SUM(M31:M32) -> 468.37155 | N33: =SUM(N31:N32) -> 628.94593 | ... Z33: =SUM(Z31:Z32) -> 1381.2446

Sheet IRR_Revenue_Model
B2: Quarterly Financial Model and Cash Flow Projections
G4: Construction & Operation Period (See Flags):
B5: Timelines and Escalation Factors: | D5: =Inputs_Assumptions!$D$4 -> Units: | G5: =DATE(YEAR(Constr_Start_Date),3,31) -> 46112 | H5: =EOMONTH(G5,Months_in_Quarter) -> 46203 | I5: =EOMONTH(H5,Months_in_Quarter) -> 46295 | J5: =EOMONTH(I5,Months_in_Quarter) -> 46387 | K5: =EOMONTH(J5,Months_in_Quarter) -> 46477 | L5: =EOMONTH(K5,Months_in_Quarter) -> 46568 | M5: =EOMONTH(L5,Months_in_Quarter) -> 46660 | N5: =EOMONTH(M5,Months_in_Quarter) -> 46752 | O5: =EOMONTH(N5,Months_in_Quarter) -> 46843 | ... FA5: =EOMONTH(EZ5,Months_in_Quarter) -> 59809
C7: Calendar Year: | D7: Year | G7: =YEAR(G5) -> 2026 | H7: =YEAR(H5) -> 2026 | I7: =YEAR(I5) -> 2026 | J7: =YEAR(J5) -> 2026 | K7: =YEAR(K5) -> 2027 | L7: =YEAR(L5) -> 2027 | M7: =YEAR(M5) -> 2027 | N7: =YEAR(N5) -> 2027 | ... FA7: =YEAR(FA5) -> 2063
C8: New Year: | D8: # | G8: 1 | H8: =IF(AND(ISNUMBER(G7),G7<>H7),1,0) -> 0 | I8: =IF(AND(ISNUMBER(H7),H7<>I7),1,0) -> 0 | J8: =IF(AND(ISNUMBER(I7),I7<>J7),1,0) -> 0 | K8: =IF(AND(ISNUMBER(J7),J7<>K7),1,0) -> 1 | L8: =IF(AND(ISNUMBER(K7),K7<>L7),1,0) -> 0 | M8: =IF(AND(ISNUMBER(L7),L7<>M7),1,0) -> 0 | N8: =IF(AND(ISNUMBER(M7),M7<>N7),1,0) -> 0 | O8: =IF(AND(ISNUMBER(N7),N7<>O7),1,0) -> 1 | ... FA8: =IF(AND(ISNUMBER(EZ7),EZ7<>FA7),1,0) -> 0
C9: Quarter of Calendar Year: | D9: # | G9: 1 | H9: =IF(H8=1,1,G9+1) -> 2 | I9: =IF(I8=1,1,H9+1) -> 3 | J9: =IF(J8=1,1,I9+1) -> 4 | K9: =IF(K8=1,1,J9+1) -> 1 | L9: =IF(L8=1,1,K9+1) -> 2 | M9: =IF(M8=1,1,L9+1) -> 3 | N9: =IF(N8=1,1,M9+1) -> 4 | O9: =IF(O8=1,1,N9+1) -> 1 | ... FA9: =IF(FA8=1,1,EZ9+1) -> 3
C11: Construction Period Flag: | D11: # | E11: =SUM(G11:EI11) -> 11 | G11: =IF(AND(G5>Constr_Start_Date,G5<=Constr_End_Date),1,0) -> 0 | H11: =IF(AND(H5>Constr_Start_Date,H5<=Constr_End_Date),1,0) -> 0 | I11: =IF(AND(I5>Constr_Start_Date,I5<=Constr_End_Date),1,0) -> 1 | J11: =IF(AND(J5>Constr_Start_Date,J5<=Constr_End_Date),1,0) -> 1 | K11: =IF(AND(K5>Constr_Start_Date,K5<=Constr_End_Date),1,0) -> 1 | L11: =IF(AND(L5>Constr_Start_Date,L5<=Constr_End_Date),1,0) -> 1 | M11: =IF(AND(M5>Constr_Start_Date,M5<=Constr_End_Date),1,0) -> 1 | N11: =IF(AND(N5>Constr_Start_Date,N5<=Constr_End_Date),1,0) -> 1 | ... FA11: =IF(AND(FA5>Constr_Start_Date,FA5<=Constr_End_Date),1,0) -> 0
C12: Refinancing Period Flag: | D12: # | E12: =SUM(G12:EI12) -> 1 | G12: =IF(AND(G5>Constr_End_Date,G5=Debt_Refinance_Date),1,0) -> 0 | H12: =IF(AND(H5>Constr_End_Date,H5=Debt_Refinance_Date),1,0) -> 0 | I12: =IF(AND(I5>Constr_End_Date,I5=Debt_Refinance_Date),1,0) -> 0 | J12: =IF(AND(J5>Constr_End_Date,J5=Debt_Refinance_Date),1,0) -> 0 | K12: =IF(AND(K5>Constr_End_Date,K5=Debt_Refinance_Date),1,0) -> 0 | L12: =IF(AND(L5>Constr_End_Date,L5=Debt_Refinance_Date),1,0) -> 0 | M12: =IF(AND(M5>Constr_End_Date,M5=Debt_Refinance_Date),1,0) -> 0 | N12: =IF(AND(N5>Constr_End_Date,N5=Debt_Refinance_Date),1,0) -> 0 | ... FA12: =IF(AND(FA5>Constr_End_Date,FA5=Debt_Refinance_Date),1,0) -> 0
C13: Refinancing Quarter #: | D13: # | E13: =MAX(G13:EI13) -> 17 | F13: 0 | G13: =IF(G12=0,(F13+1)*(1-SUM($G12:G12)),F13+1) -> 1 | H13: =IF(H12=0,(G13+1)*(1-SUM($G12:H12)),G13+1) -> 2 | I13: =IF(I12=0,(H13+1)*(1-SUM($G12:I12)),H13+1) -> 3 | J13: =IF(J12=0,(I13+1)*(1-SUM($G12:J12)),I13+1) -> 4 | K13: =IF(K12=0,(J13+1)*(1-SUM($G12:K12)),J13+1) -> 5 | L13: =IF(L12=0,(K13+1)*(1-SUM($G12:L12)),K13+1) -> 6 | M13: =IF(M12=0,(L13+1)*(1-SUM($G12:M12)),L13+1) -> 7 | N13: =IF(N12=0,(M13+1)*(1-SUM($G12:N12)),M13+1) -> 8 | ... FA13: =IF(FA12=0,(EZ13+1)*(1-SUM($G12:FA12)),EZ13+1) -> 0
C15: Operations Period Flag: | D15: # | E15: =SUM(G15:EI15) -> 127 | G15: =IF(AND(G5>Op_Start_Date,G5<=Op_End_Date),1,0) -> 0 | H15: =IF(AND(H5>Op_Start_Date,H5<=Op_End_Date),1,0) -> 0 | I15: =IF(AND(I5>Op_Start_Date,I5<=Op_End_Date),1,0) -> 0 | J15: =IF(AND(J5>Op_Start_Date,J5<=Op_End_Date),1,0) -> 0 | K15: =IF(AND(K5>Op_Start_Date,K5<=Op_End_Date),1,0) -> 0 | L15: =IF(AND(L5>Op_Start_Date,L5<=Op_End_Date),1,0) -> 0 | M15: =IF(AND(M5>Op_Start_Date,M5<=Op_End_Date),1,0) -> 1 | N15: =IF(AND(N5>Op_Start_Date,N5<=Op_End_Date),1,0) -> 1 | ... FA15: =IF(AND(FA5>Op_Start_Date,FA5<=Op_End_Date),1,0) -> 0
C16: Operational Turbine Count: | D16: # | E16: =MAX(G16:EI16) -> 103 | G16: =IF(G11=1,Constr_Phase_Model!G8,F16*G15) -> 0 | H16: =IF(H11=1,Constr_Phase_Model!H8,G16*H15) -> 0 | I16: =IF(I11=1,Constr_Phase_Model!I8,H16*I15) -> 0 | J16: =IF(J11=1,Constr_Phase_Model!J8,I16*J15) -> 0 | K16: =IF(K11=1,Constr_Phase_Model!K8,J16*K15) -> 0 | L16: =IF(L11=1,Constr_Phase_Model!L8,K16*L15) -> 6 | M16: =IF(M11=1,Constr_Phase_Model!M8,L16*M15) -> 22 | N16: =IF(N11=1,Constr_Phase_Model!N8,M16*N15) -> 30 | ... FA16: =IF(FA11=1,Constr_Phase_Model!FA8,EZ16*FA15) -> 0
C17: Electricity Generation Flag: | D17: # | E17: =SUM(G17:EI17) -> 127 | G17: =IF(AND(G5>Op_Start_Date,G5<=Op_End_Date),1,0) -> 0 | H17: =IF(AND(H5>Op_Start_Date,H5<=Op_End_Date),1,0) -> 0 | I17: =IF(AND(I5>Op_Start_Date,I5<=Op_End_Date),1,0) -> 0 | J17: =IF(AND(J5>Op_Start_Date,J5<=Op_End_Date),1,0) -> 0 | K17: =IF(AND(K5>Op_Start_Date,K5<=Op_End_Date),1,0) -> 0 | L17: =IF(AND(L5>Op_Start_Date,L5<=Op_End_Date),1,0) -> 0 | M17: =IF(AND(M5>Op_Start_Date,M5<=Op_End_Date),1,0) -> 1 | N17: =IF(AND(N5>Op_Start_Date,N5<=Op_End_Date),1,0) -> 1 | ... FA17: =IF(AND(FA5>Op_Start_Date,FA5<=Op_End_Date),1,0) -> 0
C18: Electricity Generation Quarter #: | D18: # | G18: {=SUM($G17:G17*G17)} -> 0 | H18: {=SUM($G17:H17*H17)} -> 0 | I18: {=SUM($G17:I17*I17)} -> 0 | J18: {=SUM($G17:J17*J17)} -> 0 | K18: {=SUM($G17:K17*K17)} -> 0 | L18: {=SUM($G17:L17*L17)} -> 0 | M18: {=SUM($G17:M17*M17)} -> 1 | N18: {=SUM($G17:N17*N17)} -> 2 | ... FA18: {=SUM($G17:FA17*FA17)} -> 0
C20: Electricity Rate Escalation Factor: | D20: # | F20: 1 | G20: =((1+Electr_Rate_Escalation)^(1/Quarters_in_Year))*F20 -> 1.0061922 | H20: =((1+Electr_Rate_Escalation)^(1/Quarters_in_Year))*G20 -> 1.0124228 | I20: =((1+Electr_Rate_Escalation)^(1/Quarters_in_Year))*H20 -> 1.018692 | J20: =((1+Electr_Rate_Escalation)^(1/Quarters_in_Year))*I20 -> 1.025 | K20: =((1+Electr_Rate_Escalation)^(1/Quarters_in_Year))*J20 -> 1.0313471 | L20: =((1+Electr_Rate_Escalation)^(1/Quarters_in_Year))*K20 -> 1.0377334 | M20: =((1+Electr_Rate_Escalation)^(1/Quarters_in_Year))*L20 -> 1.0441593 | N20: =((1+Electr_Rate_Escalation)^(1/Quarters_in_Year))*M20 -> 1.050625 | ... FA20: =((1+Electr_Rate_Escalation)^(1/Quarters_in_Year))*EZ20 -> 2.5399544
C21: CPI Cost Escalation Factor: | D21: # | F21: 1 | G21: =((1+CPI_Escalation)^(1/Quarters_in_Year))*F21 -> 1.0061922 | H21: =((1+CPI_Escalation)^(1/Quarters_in_Year))*G21 -> 1.0124228 | I21: =((1+CPI_Escalation)^(1/Quarters_in_Year))*H21 -> 1.018692 | J21: =((1+CPI_Escalation)^(1/Quarters_in_Year))*I21 -> 1.025 | K21: =((1+CPI_Escalation)^(1/Quarters_in_Year))*J21 -> 1.0313471 | L21: =((1+CPI_Escalation)^(1/Quarters_in_Year))*K21 -> 1.0377334 | M21: =((1+CPI_Escalation)^(1/Quarters_in_Year))*L21 -> 1.0441593 | N21: =((1+CPI_Escalation)^(1/Quarters_in_Year))*M21 -> 1.050625 | ... FA21: =((1+CPI_Escalation)^(1/Quarters_in_Year))*EZ21 -> 2.5399544
C22: RPI Cost Escalation Factor: | D22: # | F22: 1 | G22: =((1+RPI_Escalation)^(1/Quarters_in_Year))*F22 -> 1.0070501 | H22: =((1+RPI_Escalation)^(1/Quarters_in_Year))*G22 -> 1.0141499 | I22: =((1+RPI_Escalation)^(1/Quarters_in_Year))*H22 -> 1.0212997 | J22: =((1+RPI_Escalation)^(1/Quarters_in_Year))*I22 -> 1.0285 | K22: =((1+RPI_Escalation)^(1/Quarters_in_Year))*J22 -> 1.035751 | L22: =((1+RPI_Escalation)^(1/Quarters_in_Year))*K22 -> 1.0430532 | M22: =((1+RPI_Escalation)^(1/Quarters_in_Year))*L22 -> 1.0504068 | N22: =((1+RPI_Escalation)^(1/Quarters_in_Year))*M22 -> 1.0578122 | ... FA22: =((1+RPI_Escalation)^(1/Quarters_in_Year))*EZ22 -> 2.8887647
C23: Cumulative Degradation Factor: | D23: # | G23: =IF(AND(G17=1,G16=103),((1-Degradation_Factor)^(1/4))*F23,100%) -> 1 | H23: =IF(H5>Op_End_Date,0%,IF(AND(H17=1, H16=103),((1-Degradation_Factor)^(1/4))*G23,100%)) -> 1 | I23: =IF(I5>Op_End_Date,0%,IF(AND(I17=1, I16=103),((1-Degradation_Factor)^(1/4))*H23,100%)) -> 1 | J23: =IF(J5>Op_End_Date,0%,IF(AND(J17=1, J16=103),((1-Degradation_Factor)^(1/4))*I23,100%)) -> 1 | K23: =IF(K5>Op_End_Date,0%,IF(AND(K17=1, K16=103),((1-Degradation_Factor)^(1/4))*J23,100%)) -> 1 | L23: =IF(L5>Op_End_Date,0%,IF(AND(L17=1, L16=103),((1-Degradation_Factor)^(1/4))*K23,100%)) -> 1 | M23: =IF(M5>Op_End_Date,0%,IF(AND(M17=1, M16=103),((1-Degradation_Factor)^(1/4))*L23,100%)) -> 1 | N23: =IF(N5>Op_End_Date,0%,IF(AND(N17=1, N16=103),((1-Degradation_Factor)^(1/4))*M23,100%)) -> 1 | O23: =IF(O5>Op_End_Date,0%,IF(AND(O17=1, O16=103),((1-Degradation_Factor)^(1/4))*N23,100%)) -> 1 | ... FA23: =IF(FA5>Op_End_Date,0%,IF(AND(FA17=1, FA16=103),((1-Degradation_Factor)^(1/4))*EZ23,100%)) -> 0
C25: Operating Assumptions:
C26: Quarterly Load Factor: | D26: % | G26: {=_xlfn.IFS(G9=1,Inputs_Assumptions!$E$53,G9=2,Inputs_Assumptions!$E$54,G9=3,Inputs_Assumptions!$E$55,G9=4,Inputs_Assumptions!$E$56,"TRUE",0)} -> 0.30207009 | H26: {=_xlfn.IFS(H9=1,Inputs_Assumptions!$E$53,H9=2,Inputs_Assumptions!$E$54,H9=3,Inputs_Assumptions!$E$55,H9=4,Inputs_Assumptions!$E$56,"TRUE",0)} -> 0.19160291 | I26: {=_xlfn.IFS(I9=1,Inputs_Assumptions!$E$53,I9=2,Inputs_Assumptions!$E$54,I9=3,Inputs_Assumptions!$E$55,I9=4,Inputs_Assumptions!$E$56,"TRUE",0)} -> 0.19498704 | J26: {=_xlfn.IFS(J9=1,Inputs_Assumptions!$E$53,J9=2,Inputs_Assumptions!$E$54,J9=3,Inputs_Assumptions!$E$55,J9=4,Inputs_Assumptions!$E$56,"TRUE",0)} -> 0.31133996 | K26: {=_xlfn.IFS(K9=1,Inputs_Assumptions!$E$53,K9=2,Inputs_Assumptions!$E$54,K9=3,Inputs_Assumptions!$E$55,K9=4,Inputs_Assumptions!$E$56,"TRUE",0)} -> 0.30207009 | L26: {=_xlfn.IFS(L9=1,Inputs_Assumptions!$E$53,L9=2,Inputs_Assumptions!$E$54,L9=3,Inputs_Assumptions!$E$55,L9=4,Inputs_Assumptions!$E$56,"TRUE",0)} -> 0.19160291 | M26: {=_xlfn.IFS(M9=1,Inputs_Assumptions!$E$53,M9=2,Inputs_Assumptions!$E$54,M9=3,Inputs_Assumptions!$E$55,M9=4,Inputs_Assumptions!$E$56,"TRUE",0)} -> 0.19498704 | N26: {=_xlfn.IFS(N9=1,Inputs_Assumptions!$E$53,N9=2,Inputs_Assumptions!$E$54,N9=3,Inputs_Assumptions!$E$55,N9=4,Inputs_Assumptions!$E$56,"TRUE",0)} -> 0.31133996 | ... FA26: {=_xlfn.IFS(FA9=1,Inputs_Assumptions!$E$53,FA9=2,Inputs_Assumptions!$E$54,FA9=3,Inputs_Assumptions!$E$55,FA9=4,Inputs_Assumptions!$E$56,"TRUE",0)} -> 0.19498704
C27: Curtailment: | D27: % | G27: {=_xlfn.IFS(G5<Inputs_Assumptions!$E$72,Inputs_Assumptions!$E$69,G5<Inputs_Assumptions!$E$73,Inputs_Assumptions!$E$70,G5<Inputs_Assumptions!$E$74,Inputs_Assumptions!$E$71,"TRUE",0)} -> 0.0035 | H27: {=_xlfn.IFS(H5<Inputs_Assumptions!$E$72,Inputs_Assumptions!$E$69,H5<Inputs_Assumptions!$E$73,Inputs_Assumptions!$E$70,H5<Inputs_Assumptions!$E$74,Inputs_Assumptions!$E$71,"TRUE",0)} -> 0.0035 | I27: {=_xlfn.IFS(I5<Inputs_Assumptions!$E$72,Inputs_Assumptions!$E$69,I5<Inputs_Assumptions!$E$73,Inputs_Assumptions!$E$70,I5<Inputs_Assumptions!$E$74,Inputs_Assumptions!$E$71,"TRUE",0)} -> 0.0035 | J27: {=_xlfn.IFS(J5<Inputs_Assumptions!$E$72,Inputs_Assumptions!$E$69,J5<Inputs_Assumptions!$E$73,Inputs_Assumptions!$E$70,J5<Inputs_Assumptions!$E$74,Inputs_Assumptions!$E$71,"TRUE",0)} -> 0.0035 | K27: {=_xlfn.IFS(K5<Inputs_Assumptions!$E$72,Inputs_Assumptions!$E$69,K5<Inputs_Assumptions!$E$73,Inputs_Assumptions!$E$70,K5<Inputs_Assumptions!$E$74,Inputs_Assumptions!$E$71,"TRUE",0)} -> 0.0035 | L27: {=_xlfn.IFS(L5<Inputs_Assumptions!$E$72,Inputs_Assumptions!$E$69,L5<Inputs_Assumptions!$E$73,Inputs_Assumptions!$E$70,L5<Inputs_Assumptions!$E$74,Inputs_Assumptions!$E$71,"TRUE",0)} -> 0.0035 | M27: {=_xlfn.IFS(M5<Inputs_Assumptions!$E$72,Inputs_Assumptions!$E$69,M5<Inputs_Assumptions!$E$73,Inputs_Assumptions!$E$70,M5<Inputs_Assumptions!$E$74,Inputs_Assumptions!$E$71,"TRUE",0)} -> 0.0035 | N27: {=_xlfn.IFS(N5<Inputs_Assumptions!$E$72,Inputs_Assumptions!$E$69,N5<Inputs_Assumptions!$E$73,Inputs_Assumptions!$E$70,N5<Inputs_Assumptions!$E$74,Inputs_Assumptions!$E$71,"TRUE",0)} -> 0.0035 | ... FA27: {=_xlfn.IFS(FA5<Inputs_Assumptions!$E$72,Inputs_Assumptions!$E$69,FA5<Inputs_Assumptions!$E$73,Inputs_Assumptions!$E$70,FA5<Inputs_Assumptions!$E$74,Inputs_Assumptions!$E$71,"TRUE",0)} -> 0.015
C28: Annual Revenue Loss: | D28: % | G28: {=_xlfn.IFS(G5<Inputs_Assumptions!$E$63,Inputs_Assumptions!$E$58,G5<Inputs_Assumptions!$E$64,Inputs_Assumptions!$E$59,G5<Inputs_Assumptions!$E$65,Inputs_Assumptions!$E$60,G5<Inputs_Assumptions!$E$66,Inputs_Assumptions!$E$61,G5<Inputs_Assumptions!$E$74,Inputs_Assumptions!$E$62,"TRUE",0)} -> 0.025 | H28: {=_xlfn.IFS(H5<Inputs_Assumptions!$E$63,Inputs_Assumptions!$E$58,H5<Inputs_Assumptions!$E$64,Inputs_Assumptions!$E$59,H5<Inputs_Assumptions!$E$65,Inputs_Assumptions!$E$60,H5<Inputs_Assumptions!$E$66,Inputs_Assumptions!$E$61,H5<Inputs_Assumptions!$E$74,Inputs_Assumptions!$E$62,"TRUE",0)} -> 0.025 | I28: {=_xlfn.IFS(I5<Inputs_Assumptions!$E$63,Inputs_Assumptions!$E$58,I5<Inputs_Assumptions!$E$64,Inputs_Assumptions!$E$59,I5<Inputs_Assumptions!$E$65,Inputs_Assumptions!$E$60,I5<Inputs_Assumptions!$E$66,Inputs_Assumptions!$E$61,I5<Inputs_Assumptions!$E$74,Inputs_Assumptions!$E$62,"TRUE",0)} -> 0.025 | J28: {=_xlfn.IFS(J5<Inputs_Assumptions!$E$63,Inputs_Assumptions!$E$58,J5<Inputs_Assumptions!$E$64,Inputs_Assumptions!$E$59,J5<Inputs_Assumptions!$E$65,Inputs_Assumptions!$E$60,J5<Inputs_Assumptions!$E$66,Inputs_Assumptions!$E$61,J5<Inputs_Assumptions!$E$74,Inputs_Assumptions!$E$62,"TRUE",0)} -> 0.025 | K28: {=_xlfn.IFS(K5<Inputs_Assumptions!$E$63,Inputs_Assumptions!$E$58,K5<Inputs_Assumptions!$E$64,Inputs_Assumptions!$E$59,K5<Inputs_Assumptions!$E$65,Inputs_Assumptions!$E$60,K5<Inputs_Assumptions!$E$66,Inputs_Assumptions!$E$61,K5<Inputs_Assumptions!$E$74,Inputs_Assumptions!$E$62,"TRUE",0)} -> 0.025 | L28: {=_xlfn.IFS(L5<Inputs_Assumptions!$E$63,Inputs_Assumptions!$E$58,L5<Inputs_Assumptions!$E$64,Inputs_Assumptions!$E$59,L5<Inputs_Assumptions!$E$65,Inputs_Assumptions!$E$60,L5<Inputs_Assumptions!$E$66,Inputs_Assumptions!$E$61,L5<Inputs_Assumptions!$E$74,Inputs_Assumptions!$E$62,"TRUE",0)} -> 0.025 | M28: {=_xlfn.IFS(M5<Inputs_Assumptions!$E$63,Inputs_Assumptions!$E$58,M5<Inputs_Assumptions!$E$64,Inputs_Assumptions!$E$59,M5<Inputs_Assumptions!$E$65,Inputs_Assumptions!$E$60,M5<Inputs_Assumptions!$E$66,Inputs_Assumptions!$E$61,M5<Inputs_Assumptions!$E$74,Inputs_Assumptions!$E$62,"TRUE",0)} -> 0.025 | N28: {=_xlfn.IFS(N5<Inputs_Assumptions!$E$63,Inputs_Assumptions!$E$58,N5<Inputs_Assumptions!$E$64,Inputs_Assumptions!$E$59,N5<Inputs_Assumptions!$E$65,Inputs_Assumptions!$E$60,N5<Inputs_Assumptions!$E$66,Inputs_Assumptions!$E$61,N5<Inputs_Assumptions!$E$74,Inputs_Assumptions!$E$62,"TRUE",0)} -> 0.025 | ... FA28: {=_xlfn.IFS(FA5<Inputs_Assumptions!$E$63,Inputs_Assumptions!$E$58,FA5<Inputs_Assumptions!$E$64,Inputs_Assumptions!$E$59,FA5<Inputs_Assumptions!$E$65,Inputs_Assumptions!$E$60,FA5<Inputs_Assumptions!$E$66,Inputs_Assumptions!$E$61,FA5<Inputs_Assumptions!$E$74,Inputs_Assumptions!$E$62,"TRUE",0)} -> 0.08
C30: Seasonality Adjusted Net Energy Yield per Turbine: | D30: MWh / Quarter | G30: =G26*Inputs_Assumptions!$E$31 -> 20044.465 | H30: =H26*Inputs_Assumptions!$E$31 -> 12714.194 | I30: =I26*Inputs_Assumptions!$E$31 -> 12938.755 | J30: =J26*Inputs_Assumptions!$E$31 -> 20659.586 | K30: =K26*Inputs_Assumptions!$E$31 -> 20044.465 | L30: =L26*Inputs_Assumptions!$E$31 -> 12714.194 | M30: =M26*Inputs_Assumptions!$E$31 -> 12938.755 | N30: =N26*Inputs_Assumptions!$E$31 -> 20659.586 | ... FA30: =FA26*Inputs_Assumptions!$E$31 -> 12938.755
C31: P-Value Adjusted Net Energy Yield per Turbine: | D31: MWh / Quarter | G31: {=_xlfn.IFS(Inputs_Assumptions!$E$146="P50",Inputs_Assumptions!$E$38*IRR_Revenue_Model!G30,Inputs_Assumptions!$E$146="P75",Inputs_Assumptions!$E$39*IRR_Revenue_Model!G30,Inputs_Assumptions!$E$146="P90",Inputs_Assumptions!$E$40*IRR_Revenue_Model!G30,Inputs_Assumptions!$E$146="P99",Inputs_Assumptions!$E$41*IRR_Revenue_Model!G30,"TRUE",0)} -> 18194.928 | H31: {=_xlfn.IFS(Inputs_Assumptions!$E$146="P50",Inputs_Assumptions!$E$38*IRR_Revenue_Model!H30,Inputs_Assumptions!$E$146="P75",Inputs_Assumptions!$E$39*IRR_Revenue_Model!H30,Inputs_Assumptions!$E$146="P90",Inputs_Assumptions!$E$40*IRR_Revenue_Model!H30,Inputs_Assumptions!$E$146="P99",Inputs_Assumptions!$E$41*IRR_Revenue_Model!H30,"TRUE",0)} -> 11541.034 | I31: {=_xlfn.IFS(Inputs_Assumptions!$E$146="P50",Inputs_Assumptions!$E$38*IRR_Revenue_Model!I30,Inputs_Assumptions!$E$146="P75",Inputs_Assumptions!$E$39*IRR_Revenue_Model!I30,Inputs_Assumptions!$E$146="P90",Inputs_Assumptions!$E$40*IRR_Revenue_Model!I30,Inputs_Assumptions!$E$146="P99",Inputs_Assumptions!$E$41*IRR_Revenue_Model!I30,"TRUE",0)} -> 11744.874 | J31: {=_xlfn.IFS(Inputs_Assumptions!$E$146="P50",Inputs_Assumptions!$E$38*IRR_Revenue_Model!J30,Inputs_Assumptions!$E$146="P75",Inputs_Assumptions!$E$39*IRR_Revenue_Model!J30,Inputs_Assumptions!$E$146="P90",Inputs_Assumptions!$E$40*IRR_Revenue_Model!J30,Inputs_Assumptions!$E$146="P99",Inputs_Assumptions!$E$41*IRR_Revenue_Model!J30,"TRUE",0)} -> 18753.291 | K31: {=_xlfn.IFS(Inputs_Assumptions!$E$146="P50",Inputs_Assumptions!$E$38*IRR_Revenue_Model!K30,Inputs_Assumptions!$E$146="P75",Inputs_Assumptions!$E$39*IRR_Revenue_Model!K30,Inputs_Assumptions!$E$146="P90",Inputs_Assumptions!$E$40*IRR_Revenue_Model!K30,Inputs_Assumptions!$E$146="P99",Inputs_Assumptions!$E$41*IRR_Revenue_Model!K30,"TRUE",0)} -> 18194.928 | L31: {=_xlfn.IFS(Inputs_Assumptions!$E$146="P50",Inputs_Assumptions!$E$38*IRR_Revenue_Model!L30,Inputs_Assumptions!$E$146="P75",Inputs_Assumptions!$E$39*IRR_Revenue_Model!L30,Inputs_Assumptions!$E$146="P90",Inputs_Assumptions!$E$40*IRR_Revenue_Model!L30,Inputs_Assumptions!$E$146="P99",Inputs_Assumptions!$E$41*IRR_Revenue_Model!L30,"TRUE",0)} -> 11541.034 | M31: {=_xlfn.IFS(Inputs_Assumptions!$E$146="P50",Inputs_Assumptions!$E$38*IRR_Revenue_Model!M30,Inputs_Assumptions!$E$146="P75",Inputs_Assumptions!$E$39*IRR_Revenue_Model!M30,Inputs_Assumptions!$E$146="P90",Inputs_Assumptions!$E$40*IRR_Revenue_Model!M30,Inputs_Assumptions!$E$146="P99",Inputs_Assumptions!$E$41*IRR_Revenue_Model!M30,"TRUE",0)} -> 11744.874 | N31: {=_xlfn.IFS(Inputs_Assumptions!$E$146="P50",Inputs_Assumptions!$E$38*IRR_Revenue_Model!N30,Inputs_Assumptions!$E$146="P75",Inputs_Assumptions!$E$39*IRR_Revenue_Model!N30,Inputs_Assumptions!$E$146="P90",Inputs_Assumptions!$E$40*IRR_Revenue_Model!N30,Inputs_Assumptions!$E$146="P99",Inputs_Assumptions!$E$41*IRR_Revenue_Model!N30,"TRUE",0)} -> 18753.291 | ... FA31: {=_xlfn.IFS(Inputs_Assumptions!$E$146="P50",Inputs_Assumptions!$E$38*IRR_Revenue_Model!FA30,Inputs_Assumptions!$E$146="P75",Inputs_Assumptions!$E$39*IRR_Revenue_Model!FA30,Inputs_Assumptions!$E$146="P90",Inputs_Assumptions!$E$40*IRR_Revenue_Model!FA30,Inputs_Assumptions!$E$146="P99",Inputs_Assumptions!$E$41*IRR_Revenue_Model!FA30,"TRUE",0)} -> 11744.874
C32: Degradation Adjusted Net Energy Yield per Turbine: | D32: MWh / Quarter | G32: =G31*G23 -> 18194.928 | H32: =H31*H23 -> 11541.034 | I32: =I31*I23 -> 11744.874 | J32: =J31*J23 -> 18753.291 | K32: =K31*K23 -> 18194.928 | L32: =L31*L23 -> 11541.034 | M32: =M31*M23 -> 11744.874 | N32: =N31*N23 -> 18753.291 | ... FA32: =FA31*FA23 -> 0
C33: Curtailment Adjusted Net Energy Yield per Turbine: | D33: MWh / Quarter | G33: =G32*(1-G27) -> 18131.245 | H33: =H32*(1-H27) -> 11500.64 | I33: =I32*(1-I27) -> 11703.767 | J33: =J32*(1-J27) -> 18687.654 | K33: =K32*(1-K27) -> 18131.245 | L33: =L32*(1-L27) -> 11500.64 | M33: =M32*(1-M27) -> 11703.767 | N33: =N32*(1-N27) -> 18687.654 | ... FA33: =FA32*(1-FA27) -> 0
C34: Annual Revenue Loss Adjusted Net Energy Yield per Turbine: | D34: MWh / Quarter | G34: =G33*(1-G28) -> 17677.964 | H34: =H33*(1-H28) -> 11213.124 | I34: =I33*(1-I28) -> 11411.173 | J34: =J33*(1-J28) -> 18220.463 | K34: =K33*(1-K28) -> 17677.964 | L34: =L33*(1-L28) -> 11213.124 | M34: =M33*(1-M28) -> 11411.173 | N34: =N33*(1-N28) -> 18220.463 | ... FA34: =FA33*(1-FA28) -> 0
C36: Total Electricity Generation (All Turbines - Revenue, Route-to-Market Fee): | D36: MWh / Quarter | G36: =G17*G16*G34 -> 0 | H36: =H17*H16*H34 -> 0 | I36: =I17*I16*I34 -> 0 | J36: =J17*J16*J34 -> 0 | K36: =K17*K16*K34 -> 0 | L36: =L17*L16*L34 -> 0 | M36: =M17*M16*M34 -> 251045.8 | N36: =N17*N16*N34 -> 546613.88 | ... FA36: =FA17*FA16*FA34 -> 0
C37: Total Electricity Generation (All Turbines - Insurance, O&M, Connection and UoS, Seabed): | D37: MW / Quarter | G37: =G16*G17*Inputs_Assumptions!$E$26 -> 0 | H37: =H16*H17*Inputs_Assumptions!$E$26 -> 0 | I37: =I16*I17*Inputs_Assumptions!$E$26 -> 0 | J37: =J16*J17*Inputs_Assumptions!$E$26 -> 0 | K37: =K16*K17*Inputs_Assumptions!$E$26 -> 0 | L37: =L16*L17*Inputs_Assumptions!$E$26 -> 0 | M37: =M16*M17*Inputs_Assumptions!$E$26 -> 330 | N37: =N16*N17*Inputs_Assumptions!$E$26 -> 450 | ... FA37: =FA16*FA17*Inputs_Assumptions!$E$26 -> 0
C39: Escalated Electricity Rate CfD: | D39: £ / MWh | G39: =G20*CfD_Strike_Price -> 94.701204 | H39: =H20*CfD_Strike_Price -> 95.287618 | I39: =I20*CfD_Strike_Price -> 95.877662 | J39: =J20*CfD_Strike_Price -> 96.47136 | K39: =K20*CfD_Strike_Price -> 97.068734 | L39: =L20*CfD_Strike_Price -> 97.669808 | M39: =M20*CfD_Strike_Price -> 98.274603 | N39: =N20*CfD_Strike_Price -> 98.883144 | ... FA39: =FA20*CfD_Strike_Price -> 239.05644
C40: Escalated Electricity Rate Merchant Market: | D40: £ / MWh | G40: =G20*Merchant_Price*(1-Inputs_Assumptions!$E$121) -> 46.526329 | H40: =H20*Merchant_Price*(1-Inputs_Assumptions!$E$121) -> 46.814432 | I40: =I20*Merchant_Price*(1-Inputs_Assumptions!$E$121) -> 47.104318 | J40: =J20*Merchant_Price*(1-Inputs_Assumptions!$E$121) -> 47.396 | K40: =K20*Merchant_Price*(1-Inputs_Assumptions!$E$121) -> 47.689488 | L40: =L20*Merchant_Price*(1-Inputs_Assumptions!$E$121) -> 47.984793 | M40: =M20*Merchant_Price*(1-Inputs_Assumptions!$E$121) -> 48.281926 | N40: =N20*Merchant_Price*(1-Inputs_Assumptions!$E$121) -> 48.5809 | ... FA40: =FA20*Merchant_Price*(1-Inputs_Assumptions!$E$121) -> 117.44749
C42: Escalated Insurance Cost: | D42: £ / MW / Quarter | G42: =(Inputs_Assumptions!$E$112/Quarters_in_Year)*IRR_Revenue_Model!G21*Units -> 2465.171 | H42: =(Inputs_Assumptions!$E$112/Quarters_in_Year)*IRR_Revenue_Model!H21*Units -> 2480.4359 | I42: =(Inputs_Assumptions!$E$112/Quarters_in_Year)*IRR_Revenue_Model!I21*Units -> 2495.7954 | J42: =(Inputs_Assumptions!$E$112/Quarters_in_Year)*IRR_Revenue_Model!J21*Units -> 2511.25 | K42: =(Inputs_Assumptions!$E$112/Quarters_in_Year)*IRR_Revenue_Model!K21*Units -> 2526.8003 | L42: =(Inputs_Assumptions!$E$112/Quarters_in_Year)*IRR_Revenue_Model!L21*Units -> 2542.4468 | M42: =(Inputs_Assumptions!$E$112/Quarters_in_Year)*IRR_Revenue_Model!M21*Units -> 2558.1903 | N42: =(Inputs_Assumptions!$E$112/Quarters_in_Year)*IRR_Revenue_Model!N21*Units -> 2574.0313 | ... FA42: =(Inputs_Assumptions!$E$112/Quarters_in_Year)*IRR_Revenue_Model!FA21*Units -> 6222.8883
C43: Escalated Connection and UoS Charges Cost: | D43: £ / MW / Quarter | G43: =(Inputs_Assumptions!$E$113/Quarters_in_Year)*G22*Units -> 18126.902 | H43: =(Inputs_Assumptions!$E$113/Quarters_in_Year)*H22*Units -> 18254.698 | I43: =(Inputs_Assumptions!$E$113/Quarters_in_Year)*I22*Units -> 18383.395 | J43: =(Inputs_Assumptions!$E$113/Quarters_in_Year)*J22*Units -> 18513 | K43: =(Inputs_Assumptions!$E$113/Quarters_in_Year)*K22*Units -> 18643.518 | L43: =(Inputs_Assumptions!$E$113/Quarters_in_Year)*L22*Units -> 18774.957 | M43: =(Inputs_Assumptions!$E$113/Quarters_in_Year)*M22*Units -> 18907.322 | N43: =(Inputs_Assumptions!$E$113/Quarters_in_Year)*N22*Units -> 19040.62 | ... FA43: =(Inputs_Assumptions!$E$113/Quarters_in_Year)*FA22*Units -> 51997.765
C44: Escalated O&M Cost: | D44: £ / MW / Quarter | G44: =(Inputs_Assumptions!$E$114/Quarters_in_Year)*G21*Units -> 10313.471 | H44: =(Inputs_Assumptions!$E$114/Quarters_in_Year)*H21*Units -> 10377.334 | I44: =(Inputs_Assumptions!$E$114/Quarters_in_Year)*I21*Units -> 10441.593 | J44: =(Inputs_Assumptions!$E$114/Quarters_in_Year)*J21*Units -> 10506.25 | K44: =(Inputs_Assumptions!$E$114/Quarters_in_Year)*K21*Units -> 10571.307 | L44: =(Inputs_Assumptions!$E$114/Quarters_in_Year)*L21*Units -> 10636.767 | M44: =(Inputs_Assumptions!$E$114/Quarters_in_Year)*M21*Units -> 10702.633 | N44: =(Inputs_Assumptions!$E$114/Quarters_in_Year)*N21*Units -> 10768.906 | ... FA44: =(Inputs_Assumptions!$E$114/Quarters_in_Year)*FA21*Units -> 26034.533
C45: Escalated Seabed Lease Cost: | D45: £ / MW / Quarter | G45: =(Inputs_Assumptions!$E$115/Quarters_in_Year)*G22*Units -> 1007.0501 | H45: =(Inputs_Assumptions!$E$115/Quarters_in_Year)*H22*Units -> 1014.1499 | I45: =(Inputs_Assumptions!$E$115/Quarters_in_Year)*I22*Units -> 1021.2997 | J45: =(Inputs_Assumptions!$E$115/Quarters_in_Year)*J22*Units -> 1028.5 | K45: =(Inputs_Assumptions!$E$115/Quarters_in_Year)*K22*Units -> 1035.751 | L45: =(Inputs_Assumptions!$E$115/Quarters_in_Year)*L22*Units -> 1043.0532 | M45: =(Inputs_Assumptions!$E$115/Quarters_in_Year)*M22*Units -> 1050.4068 | N45: =(Inputs_Assumptions!$E$115/Quarters_in_Year)*N22*Units -> 1057.8122 | ... FA45: =(Inputs_Assumptions!$E$115/Quarters_in_Year)*FA22*Units -> 2888.7647
C46: Escalated Route to Market Fee: | D46: £ / MWh | G46: =Inputs_Assumptions!$E$116*IRR_Revenue_Model!G21 -> 2.0123845 | H46: =Inputs_Assumptions!$E$116*IRR_Revenue_Model!H21 -> 2.0248457 | I46: =Inputs_Assumptions!$E$116*IRR_Revenue_Model!I21 -> 2.037384 | J46: =Inputs_Assumptions!$E$116*IRR_Revenue_Model!J21 -> 2.05 | K46: =Inputs_Assumptions!$E$116*IRR_Revenue_Model!K21 -> 2.0626941 | L46: =Inputs_Assumptions!$E$116*IRR_Revenue_Model!L21 -> 2.0754668 | M46: =Inputs_Assumptions!$E$116*IRR_Revenue_Model!M21 -> 2.0883186 | N46: =Inputs_Assumptions!$E$116*IRR_Revenue_Model!N21 -> 2.10125 | ... FA46: =Inputs_Assumptions!$E$116*IRR_Revenue_Model!FA21 -> 5.0799088
C48: Major Maintenance Reserve Account: | D48: £M/Quarter | G48: =(Inputs_Assumptions!$E$192/Quarters_in_Year)*G21 -> 2.5154806 | H48: =(Inputs_Assumptions!$E$192/Quarters_in_Year)*H21 -> 2.5310571 | I48: =(Inputs_Assumptions!$E$192/Quarters_in_Year)*I21 -> 2.54673 | J48: =(Inputs_Assumptions!$E$192/Quarters_in_Year)*J21 -> 2.5625 | K48: =(Inputs_Assumptions!$E$192/Quarters_in_Year)*K21 -> 2.5783676 | L48: =(Inputs_Assumptions!$E$192/Quarters_in_Year)*L21 -> 2.5943335 | M48: =(Inputs_Assumptions!$E$192/Quarters_in_Year)*M21 -> 2.6103983 | N48: =(Inputs_Assumptions!$E$192/Quarters_in_Year)*N21 -> 2.6265625 | ... FA48: =(Inputs_Assumptions!$E$192/Quarters_in_Year)*FA21 -> 6.349886
C49: Decommissioning Security: | D49: £M/Quarter | G49: =(Inputs_Assumptions!$E$193/Quarters_in_Year)*G21 -> 7.5464418 | H49: =(Inputs_Assumptions!$E$193/Quarters_in_Year)*H21 -> 7.5931713 | I49: =(Inputs_Assumptions!$E$193/Quarters_in_Year)*I21 -> 7.6401901 | J49: =(Inputs_Assumptions!$E$193/Quarters_in_Year)*J21 -> 7.6875 | K49: =(Inputs_Assumptions!$E$193/Quarters_in_Year)*K21 -> 7.7351029 | L49: =(Inputs_Assumptions!$E$193/Quarters_in_Year)*L21 -> 7.7830006 | M49: =(Inputs_Assumptions!$E$193/Quarters_in_Year)*M21 -> 7.8311948 | N49: =(Inputs_Assumptions!$E$193/Quarters_in_Year)*N21 -> 7.8796875 | ... FA49: =(Inputs_Assumptions!$E$193/Quarters_in_Year)*FA21 -> 19.049658
C51: Capex per Quarter: | D51: £M | E51: =SUM(G51:FA51) -> 2434.0316 | G51: =IF(G5<=Constr_End_Date,Constr_Phase_Model!G17,0) -> 0 | H51: =IF(H5<=Constr_End_Date,Constr_Phase_Model!H17,0) -> 0 | I51: =IF(I5<=Constr_End_Date,Constr_Phase_Model!I17,0) -> 25.36875 | J51: =IF(J5<=Constr_End_Date,Constr_Phase_Model!J17,0) -> 67.65 | K51: =IF(K5<=Constr_End_Date,Constr_Phase_Model!K17,0) -> 33.825 | L51: =IF(L5<=Constr_End_Date,Constr_Phase_Model!L17,0) -> 146.01637 | M51: =IF(M5<=Constr_End_Date,Constr_Phase_Model!M17,0) -> 407.69887 | N51: =IF(N5<=Constr_End_Date,Constr_Phase_Model!N17,0) -> 260.92912 | ... FA51: =IF(FA5<=Constr_End_Date,Constr_Phase_Model!FA17,0) -> 0
C52: Interest During Construction per Quarter: | D52: £M | E52: =SUM(G52:FA52) -> 149.30938 | G52: =IF(G5<=Debt_Refinance_Date,Constr_Phase_Model!G19,0) -> 0 | H52: =IF(H5<=Debt_Refinance_Date,Constr_Phase_Model!H19,0) -> 0 | I52: =IF(I5<=Debt_Refinance_Date,Constr_Phase_Model!I19,0) -> 0 | J52: =IF(J5<=Debt_Refinance_Date,Constr_Phase_Model!J19,0) -> 0.46221678 | K52: =IF(K5<=Debt_Refinance_Date,Constr_Phase_Model!K19,0) -> 1.1328001 | L52: =IF(L5<=Debt_Refinance_Date,Constr_Phase_Model!L19,0) -> 1.4938109 | M52: =IF(M5<=Debt_Refinance_Date,Constr_Phase_Model!M19,0) -> 2.9014864 | N52: =IF(N5<=Debt_Refinance_Date,Constr_Phase_Model!N19,0) -> 6.7045939 | ... FA52: =IF(FA5<=Debt_Refinance_Date,Constr_Phase_Model!FA19,0) -> 0
C53: Loan Fee per Quarter: | D53: £M | E53: =SUM(G53:FA53) -> 1493.0798 | G53: =IF(AND(G5>=Debt_Refinance_Date,G5<CfD_Expiry_Date),($E$175+$E$176)*Inputs_Assumptions!$E$170,0) -> 0 | H53: =IF(AND(H5>=Debt_Refinance_Date,H5<CfD_Expiry_Date),($E$175+$E$176)*Inputs_Assumptions!$E$170,0) -> 0 | I53: =IF(AND(I5>=Debt_Refinance_Date,I5<CfD_Expiry_Date),($E$175+$E$176)*Inputs_Assumptions!$E$170,0) -> 0 | J53: =IF(AND(J5>=Debt_Refinance_Date,J5<CfD_Expiry_Date),($E$175+$E$176)*Inputs_Assumptions!$E$170,0) -> 0 | K53: =IF(AND(K5>=Debt_Refinance_Date,K5<CfD_Expiry_Date),($E$175+$E$176)*Inputs_Assumptions!$E$170,0) -> 0 | L53: =IF(AND(L5>=Debt_Refinance_Date,L5<CfD_Expiry_Date),($E$175+$E$176)*Inputs_Assumptions!$E$170,0) -> 0 | M53: =IF(AND(M5>=Debt_Refinance_Date,M5<CfD_Expiry_Date),($E$175+$E$176)*Inputs_Assumptions!$E$170,0) -> 0 | N53: =IF(AND(N5>=Debt_Refinance_Date,N5<CfD_Expiry_Date),($E$175+$E$176)*Inputs_Assumptions!$E$170,0) -> 0 | ... FA53: =IF(AND(FA5>=Debt_Refinance_Date,FA5<CfD_Expiry_Date),($E$175+$E$176)*Inputs_Assumptions!$E$170,0) -> 0
...

Sheet Sensitivity_Table
B2: Scenario | C2: Value | D2: Case | F2: Construction Period Debt | G2: Construction Period Gearing Ratio | H2: Operation Period Debt | I2: Operations Period Gearing Ratio | K2: Total Invest Equity | L2: Equity IRR | M2: Cash on cash multiple | N2: Net Refinancing Proceeds | O2: Terminal Value at Exit | Q2: Median DSCR | R2: Minimum DSCR
B4: Base P50 | C4: - | D4: P50 | F4: 1625.2044 | G4: 0.65 | H4: 2073.8317 | I4: 0.69237364 | K4: 1196.7367 | L4: 0.10405264 | M4: 1.5662523 | N4: 739.0386 | O4: 2781.2733 | Q4: 1.2998264 | R4: 1.1862792 | T4: Base case: Capex contigency of 2.5%, Construction Capex of 2524 (£/kW), Infrastructure Capex of 550 (£/kW), O&M Opex of 41 (£ / MW / Year), Connection & UoS Opex of 72 (£ / MW / Year), Construction Debt Interest Rate of 5.85%, First Lien Interest Rate of 5.9%, Second Lien Interest Rate of 6.6%, Electricity Rate Escalation Factor of 2%, Annual Degradation Factor of 0.2%
B5: Base P75 | C5: - | D5: P75 | F5: 1621.8698 | G5: 0.65 | H5: 1914.7488 | I5: 0.67504477 | K5: 1197.0469 | L5: 0.06401144 | M5: 1.3450815 | N5: 552.34159 | O5: 2573.826 | Q5: 1.2998277 | R5: 1.1756393
B6: Base P90 | C6: - | D6: P90 | F6: 1618.8685 | G6: 0.65 | H6: 1771.5691 | I6: 0.65770148 | K6: 1197.3262 | L6: 0.027292004 | M6: 1.1460508 | N6: 384.30846 | O6: 2387.117 | Q6: 1.299829 | R6: 1.1644297
B7: Base P99 | C7: - | D7: P99 | F7: 1613.7031 | G7: 0.65 | H7: 1525.1468 | I7: 0.62311049 | K7: 1197.8068 | L7: -0.03706113 | M7: 0.80369804 | N7: 95.111558 | O7: 2065.7776 | Q7: 1.2998319 | R7: 1.1402109
B9: Capex Contigency - 1 | C9: 0.02 | D9: P50 | F9: 1617.4868 | G9: 0.65 | H9: 2073.8317 | I9: 0.6934189 | K9: 1192.2216 | L9: 0.10633513 | M9: 1.579217 | N9: 747.42369 | O9: 2781.2733 | Q9: 1.2998264 | R9: 1.1862792
B10: Capex Contigency - 1 | C10: 0.02 | D10: P75 | F10: 1614.1521 | G10: 0.65 | H10: 1914.7488 | I10: 0.67612101 | K10: 1192.5319 | L10: 0.066208795 | M10: 1.3572054 | N10: 560.72668 | O10: 2573.826 | Q10: 1.2998277 | R10: 1.1756393
B11: Capex Contigency - 1 | C11: 0.02 | D11: P90 | F11: 1611.1509 | G11: 0.65 | H11: 1771.5691 | I11: 0.65880578 | K11: 1192.8111 | L11: 0.029397383 | M11: 1.1574185 | N11: 392.69354 | O11: 2387.117 | Q11: 1.299829 | R11: 1.1644297
B12: Capex Contigency - 1 | C12: 0.02 | D12: P99 | F12: 1605.9855 | G12: 0.65 | H12: 1525.1468 | I12: 0.62426204 | K12: 1193.2918 | L12: -0.035145129 | M12: 0.81376583 | N12: 103.49664 | O12: 2065.7776 | Q12: 1.2998319 | R12: 1.1402109
B14: Capex Contigency - 2 | C14: 0.05 | D14: P50 | F14: 1663.7927 | G14: 0.65 | H14: 2073.8317 | I14: 0.68719425 | K14: 1219.3119 | L14: 0.092817315 | M14: 1.5028691 | N14: 697.11319 | O14: 2781.2733 | Q14: 1.2998264 | R14: 1.1862792
B15: Capex Contigency - 2 | C15: 0.05 | D15: P75 | F15: 1660.4581 | G15: 0.65 | H15: 1914.7488 | I15: 0.66971458 | K15: 1219.6222 | L15: 0.053211507 | M15: 1.2858083 | N15: 510.41618 | O15: 2573.826 | Q15: 1.2998277 | R15: 1.1756393
B16: Capex Contigency - 2 | C16: 0.05 | D16: P90 | F16: 1657.4568 | G16: 0.65 | H16: 1771.5691 | I16: 0.65223501 | K16: 1219.9014 | L16: 0.016957626 | M16: 1.0904743 | N16: 342.38305 | O16: 2387.117 | Q16: 1.299829 | R16: 1.1644297
B17: Capex Contigency - 2 | C17: 0.05 | D17: P99 | F17: 1652.2914 | G17: 0.65 | H17: 1525.1468 | I17: 0.61741589 | K17: 1220.382 | L17: -0.046447875 | M17: 0.75447651 | N17: 53.186144 | O17: 2065.7776 | Q17: 1.2998319 | R17: 1.1402109
B19: Construction Capex - 1 | C19: 2148 | D19: P50 | F19: 1431.6854 | G19: 0.65 | H19: 2073.8317 | I19: 0.71945843 | K19: 1083.9773 | L19: 0.16409104 | M19: 1.9223667 | N19: 948.44891 | O19: 2781.2733 | Q19: 1.2998264 | R19: 1.1862792
B20: Construction Capex - 1 | C20: 2148 | D20: P75 | F20: 1428.3508 | G20: 0.65 | H20: 1914.7488 | I20: 0.702991 | K20: 1084.2875 | L20: 0.12234246 | M20: 1.6780936 | N20: 761.7519 | O20: 2573.826 | Q20: 1.2998277 | R20: 1.1756393
B21: Construction Capex - 1 | C21: 2148 | D21: P90 | F21: 1425.3495 | G21: 0.65 | H21: 1771.5691 | I21: 0.68643735 | K21: 1084.5668 | L21: 0.08364118 | M21: 1.4582845 | N21: 593.71877 | O21: 2387.117 | Q21: 1.299829 | R21: 1.1644297
